---
title: 'JavaScript Promise catch() Method: Comprehensive Guide with Examples'
date: '2024-10-27'
lastmod: '2024-10-27'
tags: ['javascript', 'promise', 'catch', 'error handling', 'asynchronous', 'es6']
draft: false
summary: 'Learn how to effectively handle errors in JavaScript Promises using the catch() method. This comprehensive guide provides detailed explanations, practical examples, and best practices for robust error handling in asynchronous JavaScript code.'
authors: ['default']
---

# Mastering JavaScript Promises: A Deep Dive into the `catch()` Method

JavaScript Promises are a cornerstone of modern asynchronous programming. They provide a clean and structured way to handle operations that might take some time to complete, such as fetching data from an API or reading a file. While the `then()` method allows you to handle successful resolutions, the `catch()` method is crucial for gracefully managing rejections, or errors, that might occur during the Promise lifecycle. This blog post delves into the intricacies of the `catch()` method, providing a comprehensive guide with practical examples to help you become a Promise pro.

## What are JavaScript Promises?

Before diving into `catch()`, let's briefly recap what Promises are.  A Promise represents the eventual completion (or failure) of an asynchronous operation and its resulting value. It can be in one of three states:

*   **Pending:** The initial state; neither fulfilled nor rejected.
*   **Fulfilled (Resolved):** The operation completed successfully.
*   **Rejected:** The operation failed.

Promises help avoid the infamous "callback hell" and make asynchronous code more readable and maintainable.

## The Importance of Error Handling with Promises

Asynchronous operations are inherently prone to errors. Network issues, invalid data, or unexpected server responses can all cause a Promise to reject.  Without proper error handling, your application might crash, display incorrect information, or behave unpredictably.  The `catch()` method is your primary tool for preventing these issues.

## Introduction to the `catch()` Method

The `catch()` method is a function attached to a Promise that handles rejected Promises.  It allows you to gracefully deal with errors that occur during the Promise's execution. The `catch()` method accepts a single argument: a callback function that will be executed if the Promise rejects.

**Syntax:**

```javascript
promise.catch(err => {
  // Handle the error here
  console.error("An error occurred:", err);
});
```

Here, `promise` is the Promise object, and the `err` argument in the callback function represents the reason for the rejection (often an `Error` object).

## Basic Example: Catching a Simple Error

Let's start with a simple example that demonstrates the basic usage of `catch()`:

```javascript
const myPromise = new Promise((resolve, reject) => {
  setTimeout(() => {
    const randomNumber = Math.random();
    if (randomNumber < 0.5) {
      resolve("Success!");
    } else {
      reject(new Error("Something went wrong!"));
    }
  }, 500); // Simulate an asynchronous operation with a 500ms delay
});

myPromise
  .then(value => {
    console.log("Resolved:", value);
  })
  .catch(error => {
    console.error("Rejected:", error);
  });
```

In this example, the Promise randomly either resolves with "Success!" or rejects with an `Error` object. The `catch()` method ensures that we handle the rejection gracefully, logging the error to the console.

## Chaining `catch()` Handlers

Promises support chaining, which allows you to sequence multiple asynchronous operations. You can also chain `catch()` handlers to handle errors at different points in the chain.

```javascript
const fetchData = () => {
  return new Promise((resolve, reject) => {
    setTimeout(() => {
      const success = Math.random() > 0.2; // Simulate 80% success rate
      if (success) {
        resolve({ data: "Data from the API" });
      } else {
        reject(new Error("Failed to fetch data"));
      }
    }, 500);
  });
};

const processData = (data) => {
  return new Promise((resolve, reject) => {
    setTimeout(() => {
      if (data && data.data) {
        resolve(`Processed: ${data.data}`);
      } else {
        reject(new Error("Invalid data received"));
      }
    }, 300);
  });
};

fetchData()
  .then(data => processData(data))
  .then(processedData => {
    console.log("Final Result:", processedData);
  })
  .catch(error => {
    console.error("An error occurred during the process:", error);
  });
```

In this example, if `fetchData()` rejects, the `catch()` handler will be executed, and the subsequent `then()` handlers will be skipped. Critically, the `catch()` handler at the end of the chain handles *any* error occurring in *any* of the previous `then` handlers.

##  Using `catch()` for Specific Errors

You can filter errors within a `catch()` handler to handle specific types of errors differently.

```javascript
const divide = (a, b) => {
  return new Promise((resolve, reject) => {
    if (b === 0) {
      reject(new Error("Cannot divide by zero"));
    } else {
      resolve(a / b);
    }
  });
};

divide(10, 0)
  .then(result => console.log("Result:", result))
  .catch(error => {
    if (error.message === "Cannot divide by zero") {
      console.error("Division by zero detected!");
    } else {
      console.error("An unexpected error occurred:", error);
    }
  });

divide(10,2)
.then(result => console.log("Result:", result))
.catch(error => { // This catch will not be executed
    console.error("This will not log in the second call");
});
```

Here, the `catch()` handler checks the error message and handles the "Cannot divide by zero" error specifically. This allows for more granular error handling.

## `catch()` vs. `finally()`

It's important to distinguish `catch()` from `finally()`.  The `finally()` method is executed regardless of whether the Promise resolves or rejects. It's typically used for cleanup operations, such as closing connections or releasing resources.

```javascript
const fetchDataWithFinally = () => {
  return new Promise((resolve, reject) => {
    setTimeout(() => {
      const success = Math.random() > 0.5;
      if (success) {
        resolve("Data fetched successfully");
      } else {
        reject(new Error("Failed to fetch data"));
      }
    }, 500);
  });
};

fetchDataWithFinally()
  .then(result => console.log("Result:", result))
  .catch(error => console.error("Error:", error))
  .finally(() => console.log("Fetch operation complete (regardless of success or failure)"));
```

## Async/Await and `try...catch`

When using `async/await`, which is syntactic sugar over Promises, you can use `try...catch` blocks for error handling, providing a more synchronous-looking approach.

```javascript
async function fetchDataAsync() {
  try {
    const response = await fetch('https://api.example.com/data'); // Replace with an actual API endpoint
    if (!response.ok) {
      throw new Error(`HTTP error! Status: ${response.status}`);
    }
    const data = await response.json();
    console.log("Data:", data);
  } catch (error) {
    console.error("An error occurred:", error);
  } finally {
    console.log("Async Fetch complete.");
  }
}

fetchDataAsync();
```

This is equivalent to a Promise chain with `.then()` and `.catch()`, but it often leads to more readable code, especially for complex asynchronous operations.

## Best Practices for Using `catch()`

*   **Always include a `catch()` handler:** Even if you don't anticipate errors, including a `catch()` handler provides a safety net and prevents unhandled rejections from crashing your application.
*   **Handle errors appropriately:**  Log errors, display user-friendly messages, or retry the operation if appropriate.
*   **Avoid swallowing errors:** Don't simply catch an error and do nothing.  This can hide problems and make debugging difficult.  At a minimum, log the error.
*   **Use `try...catch` for async/await:**  `try...catch` often leads to more readable error handling when working with `async/await`.
*   **Consider using a global error handler:** For critical errors that should always be logged or reported, you can set up a global error handler to catch unhandled Promise rejections.

## Advanced Error Handling: Re-throwing Errors

Sometimes, you might want to perform some cleanup or logging within a `catch()` handler and then re-throw the error to be handled further up the chain or by a global error handler.  You can do this by throwing the error again within the `catch()` handler.

```javascript
function doSomethingThatMightFail() {
  return new Promise((resolve, reject) => {
    setTimeout(() => {
      if (Math.random() < 0.3) {
        reject(new Error("Operation failed!"));
      } else {
        resolve("Operation successful!");
      }
    }, 200);
  });
}

doSomethingThatMightFail()
  .then(result => console.log("Result:", result))
  .catch(error => {
    console.error("Caught an error:", error);
    // Perform some cleanup here, e.g., logging to an error reporting service
    throw error; // Re-throw the error to be handled elsewhere
  })
  .catch(globalErrorHandler); // Catch the re-thrown error with a global handler. The globalErrorHandler needs to be implemented.

function globalErrorHandler(error) {
    console.error("Global Error Handler: ", error);
}

```

## Conclusion

The `catch()` method is an essential part of working with JavaScript Promises. It allows you to gracefully handle errors that might occur during asynchronous operations, preventing crashes and ensuring a more robust and user-friendly application. By understanding the different ways to use `catch()`, including chaining, filtering errors, and using `try...catch` with `async/await`, you can significantly improve the quality and reliability of your JavaScript code. Remember to always include a `catch()` handler, handle errors appropriately, and avoid swallowing errors to create well-behaved and maintainable applications.  Happy coding!