---
title: 'Promise.reject() in JavaScript: Mastering Asynchronous Error Handling'
date: '2024-10-27'
lastmod: '2024-10-27'
tags: ['javascript', 'promise', 'promise.reject', 'async', 'asynchronous', 'error handling', 'promise methods', 'js']
draft: false
summary: 'Learn how to effectively use Promise.reject() in JavaScript for handling errors in asynchronous operations. This comprehensive guide covers syntax, use cases, error propagation, and best practices for robust error handling in your JavaScript applications.'
authors: ['default']
---

# Promise.reject() in JavaScript: Mastering Asynchronous Error Handling

Asynchronous programming is a cornerstone of modern JavaScript development, particularly in web applications that handle network requests, user interactions, and other time-consuming operations.  Promises provide a powerful mechanism for managing asynchronous code, and understanding how to handle errors within Promises is crucial for building reliable and robust applications.  This comprehensive guide explores `Promise.reject()`, a key method for explicitly creating rejected Promises, allowing you to effectively manage errors in your asynchronous workflows.

## What is `Promise.reject()`?

`Promise.reject()` is a static method of the `Promise` object in JavaScript.  It creates a new `Promise` object that is immediately rejected with a given reason (the rejection value). This allows you to signal that an asynchronous operation has failed and provide information about the failure.

**Syntax:**

```javascript
Promise.reject(reason);
```

*   **`reason`**:  The value with which the `Promise` will be rejected.  This can be any JavaScript value, but it's common to use an `Error` object or a descriptive string.

**Return Value:**

A new `Promise` object that is rejected with the provided `reason`.

## Basic Examples

Let's start with some simple examples to illustrate how `Promise.reject()` works:

```javascript
const rejectedPromise = Promise.reject("Something went wrong!");

rejectedPromise
  .then(() => {
    // This will never be executed because the promise is rejected.
    console.log("Promise resolved (this shouldn't happen)");
  })
  .catch(error => {
    console.error("Promise rejected:", error); // Output: Promise rejected: Something went wrong!
  });
```

In this example, we create a rejected Promise with the string "Something went wrong!" as the rejection reason. The `catch()` method is used to handle the rejection.  The `then()` method is skipped because the Promise never resolves.

Another example using an `Error` object:

```javascript
const rejectedPromiseWithError = Promise.reject(new Error("Failed to fetch data"));

rejectedPromiseWithError
  .then(() => {
    console.log("Promise resolved (this shouldn't happen)");
  })
  .catch(error => {
    console.error("Promise rejected:", error.message); // Output: Promise rejected: Failed to fetch data
    console.error("Error Stack:", error.stack); // Output: Stack trace of the error
  });
```

Using an `Error` object is generally recommended because it provides more detailed information about the error, including a stack trace, which can be invaluable for debugging.

## Use Cases for `Promise.reject()`

`Promise.reject()` is useful in several scenarios:

1.  **Explicitly Rejecting a Promise:**  When a function that returns a Promise encounters an error condition that prevents it from fulfilling its purpose, you can use `Promise.reject()` to signal the failure.

    ```javascript
    function fetchData(url) {
      return new Promise((resolve, reject) => {
        if (!url) {
          reject(new Error("URL is required"));
          return; // Important to stop execution
        }

        // Simulate a network request
        setTimeout(() => {
          const success = Math.random() > 0.5; // Simulate success or failure

          if (success) {
            resolve({ data: "Data fetched successfully" });
          } else {
            reject(new Error("Failed to fetch data from " + url));
          }
        }, 1000);
      });
    }

    fetchData("https://example.com/api/data")
      .then(response => {
        console.log("Data:", response.data);
      })
      .catch(error => {
        console.error("Error fetching data:", error.message);
      });

    fetchData("") // Will trigger the 'URL is required' rejection
      .then(response => {
        console.log("Data:", response.data);
      })
      .catch(error => {
        console.error("Error fetching data:", error.message); // Output: Error fetching data: URL is required
      });

    ```

    In this example, the `fetchData` function uses `Promise.reject()` to handle the case where the URL is missing.  It also simulates a potential network error using `setTimeout` and a random number.

2.  **Transforming Synchronous Errors into Rejected Promises:**  If you're working with a synchronous function that might throw an error, you can wrap it in a `Promise` and use `Promise.reject()` to convert the synchronous error into a rejected Promise.

    ```javascript
    function synchronousFunction(input) {
      if (input < 0) {
        throw new Error("Input must be non-negative");
      }
      return input * 2;
    }

    function asyncWrapper(input) {
      return new Promise((resolve, reject) => {
        try {
          const result = synchronousFunction(input);
          resolve(result);
        } catch (error) {
          reject(error); // Convert synchronous error to a rejected Promise
        }
      });
    }

    asyncWrapper(5)
      .then(result => {
        console.log("Result:", result); // Output: Result: 10
      })
      .catch(error => {
        console.error("Error:", error.message);
      });

    asyncWrapper(-1)
      .then(result => {
        console.log("Result:", result);
      })
      .catch(error => {
        console.error("Error:", error.message); // Output: Error: Input must be non-negative
      });
    ```

    The `asyncWrapper` function encapsulates the `synchronousFunction`.  If `synchronousFunction` throws an error, `asyncWrapper` catches it and uses `Promise.reject()` to create a rejected Promise, allowing you to handle the error using standard Promise error handling techniques.

3.  **Short-Circuiting Promise Chains:** You can use `Promise.reject()` within a `.then()` callback to short-circuit a Promise chain. This means that if a condition is not met, you can immediately reject the Promise and prevent subsequent `.then()` callbacks from executing.

    ```javascript
    function validateData(data) {
      return new Promise((resolve, reject) => {
        if (!data || typeof data !== 'object') {
          reject(new Error("Invalid data format"));
          return;
        }
        if (!data.name || typeof data.name !== 'string') {
            reject(new Error("Data must have a name property of type string."));
            return;
        }
        resolve(data);
      });
    }

    function processData(data) {
      return new Promise(resolve => {
        // Simulate some processing
        setTimeout(() => {
          const processedData = { ...data, processed: true };
          resolve(processedData);
        }, 500);
      });
    }

    const myData = { name: "Example", value: 123 }; //Valid Data
    const badData  = { value: 123 }; //Missing Name, invalid Data
    const nonObjectData  = "string"; //Missing Name, invalid Data

    validateData(myData)
      .then(data => processData(data))
      .then(processedData => {
        console.log("Processed data:", processedData); // Output: Processed data: { name: 'Example', value: 123, processed: true }
      })
      .catch(error => {
        console.error("Error processing data:", error.message);
      });

    validateData(badData)
      .then(data => processData(data))
      .then(processedData => {
        console.log("Processed data:", processedData);
      })
      .catch(error => {
        console.error("Error processing data:", error.message); //Data must have a name property of type string.
      });

      validateData(nonObjectData)
      .then(data => processData(data))
      .then(processedData => {
        console.log("Processed data:", processedData);
      })
      .catch(error => {
        console.error("Error processing data:", error.message); //Invalid data format
      });
    ```

    In this example, if the `validateData` function determines that the input data is invalid, it rejects the Promise, preventing the `processData` function from being executed.

## Error Propagation

When a `Promise` is rejected, the rejection is propagated down the Promise chain until a `.catch()` handler is encountered.  If no `.catch()` handler is found, the rejection will result in an unhandled rejection error.

```javascript
Promise.resolve(1)
  .then(value => {
    // Simulate an error condition
    if (value > 0) {
      return Promise.reject(new Error("Value is too large"));
    }
    return value * 2;
  })
  .then(result => {
    console.log("Result:", result); // This will not be executed
  })
  .catch(error => {
    console.error("Error:", error.message); // Output: Error: Value is too large
  });
```

In this example, the `Promise` resolves to `1`, but the first `.then()` callback rejects the `Promise` because the value is greater than 0. The second `.then()` callback is skipped, and the `.catch()` handler catches the rejection.

## Best Practices for Using `Promise.reject()`

*   **Use `Error` objects for Rejection Reasons:**  Whenever possible, use `Error` objects as the rejection reason. This provides valuable debugging information, including the stack trace.
*   **Provide Descriptive Error Messages:**  Make sure your error messages are clear and descriptive, providing enough information to understand why the error occurred and how to fix it.
*   **Handle Rejections Appropriately:** Always include a `.catch()` handler to handle potential rejections.  Unhandled rejections can lead to unexpected behavior and make it difficult to debug your code.
*   **Avoid Throwing Errors in Async Functions (when using async/await):** While you can use `try...catch` blocks with `async/await`, prefer returning a rejected promise instead, especially if you want to maintain compatibility with existing Promise-based code.
*   **Consider Using `try...catch` for Synchronous Errors:**  While `Promise.reject()` can handle synchronous errors, using `try...catch` directly within the `Promise` constructor is often a more straightforward approach.
*   **Avoid Mixing Callback and Promise Styles:** While technically possible, mixing old-style callbacks with promises can lead to confusing and difficult-to-debug code. Strive for consistency in your asynchronous programming approach.

## `Promise.reject()` vs. `throw` in `async` Functions

When using `async/await`, the `throw` keyword can also be used to signal an error.  However, it's important to understand the difference between `throw` and `Promise.reject()`.

*   **`throw`**: Throws an exception that can be caught by a `try...catch` block within the `async` function.  If the exception is not caught, it will propagate up the call stack.

*   **`Promise.reject()`**:  Creates a rejected `Promise` that will be handled by the nearest `.catch()` handler in the Promise chain.

Inside an `async` function, `throw` is implicitly converted into a rejected Promise.

```javascript
async function myAsyncFunction(input) {
  if (input < 0) {
    throw new Error("Input must be non-negative"); // Equivalent to returning Promise.reject(new Error("Input must be non-negative"));
  }
  return input * 2;
}

myAsyncFunction(-1)
  .then(result => {
    console.log("Result:", result);
  })
  .catch(error => {
    console.error("Error:", error.message); // Output: Error: Input must be non-negative
  });

//Example with try/catch
async function myFunctionWithTryCatch(input) {
  try {
    if (input < 0) {
      throw new Error("Input must be non-negative");
    }
    return input * 2;
  } catch (error) {
    console.error("Error within function:", error.message);
    return Promise.reject(error); //Reject with the same error object
  }
}

myFunctionWithTryCatch(-1)
    .then(result => {
        console.log("Result:", result)
    })
    .catch(error => {
      console.error("Error from Promise:", error.message); // Output: Error: Input must be non-negative
    })
```

While `throw` is convenient, it's generally recommended to use `Promise.reject()` explicitly, particularly when dealing with functions that might be used in a wider Promise chain.  This makes the error handling more explicit and predictable.  The example with try/catch provides a way to catch the synchronous error, log it for debugging, and then propagate it as a rejected promise so that the calling function can handle it in a standardized way.

## Conclusion

`Promise.reject()` is a fundamental tool for managing errors in asynchronous JavaScript code using Promises. By understanding its syntax, use cases, and best practices, you can write more robust and maintainable applications that effectively handle errors and prevent unexpected behavior.  By employing descriptive error messages and proper error handling with `.catch()`, you can ensure your asynchronous code gracefully recovers from errors and provides a better user experience.